package com.revature.exceptions;

public class UnderstandingExceptions {
	public static void main(String[] args) {
		int arr[] = new int[4];
		arr[0] = 1;
		try {
			arr[4] = 50;
		} catch (ArrayIndexOutOfBoundsException e) {
			System.out.println("arr[4] inaccessible");
			System.out.println(e.getMessage());
			throw new Exception();
		} finally {
			System.out.println("Finally despite returning in catch");
		}
	}
}
