package com.revature.exceptions;

public class UnderstandingExceptions {
	public static void main(String[] args) throws Exception {
		int arr[] = new int[4];
		String s = null;
		arr[0] = 1;
		try {
			arr[4] = 50;
			s.codePoints();
		} catch (ArrayIndexOutOfBoundsException e) {
			System.err.println("arr[4] inaccessible");
			System.err.println(e.getMessage());
			throw new Exception();
		} catch (NullPointerException e) {
			
		} finally {
			System.err.println("Finally despite returning in catch");
		}
	}
}
